[2025-03-30 22:19:26,713] {taskinstance.py:1032} INFO - Dependencies all met for <TaskInstance: natality_web_data_to_gcs.upload_race_lookup manual__2025-03-30T22:19:16.133079+00:00 [queued]>
[2025-03-30 22:19:26,732] {taskinstance.py:1032} INFO - Dependencies all met for <TaskInstance: natality_web_data_to_gcs.upload_race_lookup manual__2025-03-30T22:19:16.133079+00:00 [queued]>
[2025-03-30 22:19:26,732] {taskinstance.py:1238} INFO - 
--------------------------------------------------------------------------------
[2025-03-30 22:19:26,732] {taskinstance.py:1239} INFO - Starting attempt 1 of 1
[2025-03-30 22:19:26,732] {taskinstance.py:1240} INFO - 
--------------------------------------------------------------------------------
[2025-03-30 22:19:26,750] {taskinstance.py:1259} INFO - Executing <Task(PythonOperator): upload_race_lookup> on 2025-03-30 22:19:16.133079+00:00
[2025-03-30 22:19:26,763] {standard_task_runner.py:52} INFO - Started process 249 to run task
[2025-03-30 22:19:26,769] {standard_task_runner.py:76} INFO - Running: ['***', 'tasks', 'run', 'natality_web_data_to_gcs', 'upload_race_lookup', 'manual__2025-03-30T22:19:16.133079+00:00', '--job-id', '81', '--raw', '--subdir', 'DAGS_FOLDER/bigquery_to_gcs.py', '--cfg-path', '/tmp/tmptou0r46u', '--error-file', '/tmp/tmp19b7hpj0']
[2025-03-30 22:19:26,774] {standard_task_runner.py:77} INFO - Job 81: Subtask upload_race_lookup
[2025-03-30 22:19:26,866] {logging_mixin.py:109} INFO - Running <TaskInstance: natality_web_data_to_gcs.upload_race_lookup manual__2025-03-30T22:19:16.133079+00:00 [running]> on host 6e74f7e5ce4c
[2025-03-30 22:19:26,963] {taskinstance.py:1426} INFO - Exporting the following env vars:
AIRFLOW_CTX_DAG_OWNER=***
AIRFLOW_CTX_DAG_ID=natality_web_data_to_gcs
AIRFLOW_CTX_TASK_ID=upload_race_lookup
AIRFLOW_CTX_EXECUTION_DATE=2025-03-30T22:19:16.133079+00:00
AIRFLOW_CTX_DAG_RUN_ID=manual__2025-03-30T22:19:16.133079+00:00
[2025-03-30 22:19:26,966] {taskinstance.py:1700} ERROR - Task failed with exception
Traceback (most recent call last):
  File "/home/airflow/.local/lib/python3.6/site-packages/airflow/models/taskinstance.py", line 1329, in _run_raw_task
    self._execute_task_with_callbacks(context)
  File "/home/airflow/.local/lib/python3.6/site-packages/airflow/models/taskinstance.py", line 1455, in _execute_task_with_callbacks
    result = self._execute_task(context, self.task)
  File "/home/airflow/.local/lib/python3.6/site-packages/airflow/models/taskinstance.py", line 1511, in _execute_task
    result = execute_callable(context=context)
  File "/home/airflow/.local/lib/python3.6/site-packages/airflow/operators/python.py", line 174, in execute
    return_value = self.execute_callable()
  File "/home/airflow/.local/lib/python3.6/site-packages/airflow/operators/python.py", line 185, in execute_callable
    return self.python_callable(*self.op_args, **self.op_kwargs)
TypeError: upload_local_file_to_gcs() takes 1 positional argument but 15 were given
[2025-03-30 22:19:26,993] {taskinstance.py:1277} INFO - Marking task as FAILED. dag_id=natality_web_data_to_gcs, task_id=upload_race_lookup, execution_date=20250330T221916, start_date=20250330T221926, end_date=20250330T221926
[2025-03-30 22:19:27,069] {standard_task_runner.py:92} ERROR - Failed to execute job 81 for task upload_race_lookup
Traceback (most recent call last):
  File "/home/airflow/.local/lib/python3.6/site-packages/airflow/task/task_runner/standard_task_runner.py", line 85, in _start_by_fork
    args.func(args, dag=self.dag)
  File "/home/airflow/.local/lib/python3.6/site-packages/airflow/cli/cli_parser.py", line 48, in command
    return func(*args, **kwargs)
  File "/home/airflow/.local/lib/python3.6/site-packages/airflow/utils/cli.py", line 92, in wrapper
    return f(*args, **kwargs)
  File "/home/airflow/.local/lib/python3.6/site-packages/airflow/cli/commands/task_command.py", line 298, in task_run
    _run_task_by_selected_method(args, dag, ti)
  File "/home/airflow/.local/lib/python3.6/site-packages/airflow/cli/commands/task_command.py", line 107, in _run_task_by_selected_method
    _run_raw_task(args, ti)
  File "/home/airflow/.local/lib/python3.6/site-packages/airflow/cli/commands/task_command.py", line 184, in _run_raw_task
    error_file=args.error_file,
  File "/home/airflow/.local/lib/python3.6/site-packages/airflow/utils/session.py", line 70, in wrapper
    return func(*args, session=session, **kwargs)
  File "/home/airflow/.local/lib/python3.6/site-packages/airflow/models/taskinstance.py", line 1329, in _run_raw_task
    self._execute_task_with_callbacks(context)
  File "/home/airflow/.local/lib/python3.6/site-packages/airflow/models/taskinstance.py", line 1455, in _execute_task_with_callbacks
    result = self._execute_task(context, self.task)
  File "/home/airflow/.local/lib/python3.6/site-packages/airflow/models/taskinstance.py", line 1511, in _execute_task
    result = execute_callable(context=context)
  File "/home/airflow/.local/lib/python3.6/site-packages/airflow/operators/python.py", line 174, in execute
    return_value = self.execute_callable()
  File "/home/airflow/.local/lib/python3.6/site-packages/airflow/operators/python.py", line 185, in execute_callable
    return self.python_callable(*self.op_args, **self.op_kwargs)
TypeError: upload_local_file_to_gcs() takes 1 positional argument but 15 were given
[2025-03-30 22:19:27,110] {local_task_job.py:154} INFO - Task exited with return code 1
[2025-03-30 22:19:27,183] {local_task_job.py:264} INFO - 0 downstream tasks scheduled from follow-on schedule check
