[2025-03-31 00:05:56,599] {taskinstance.py:1032} INFO - Dependencies all met for <TaskInstance: natality_web_data_to_gcs.create_dataproc_cluster manual__2025-03-31T00:05:20.585572+00:00 [queued]>
[2025-03-31 00:05:56,621] {taskinstance.py:1032} INFO - Dependencies all met for <TaskInstance: natality_web_data_to_gcs.create_dataproc_cluster manual__2025-03-31T00:05:20.585572+00:00 [queued]>
[2025-03-31 00:05:56,622] {taskinstance.py:1238} INFO - 
--------------------------------------------------------------------------------
[2025-03-31 00:05:56,622] {taskinstance.py:1239} INFO - Starting attempt 1 of 1
[2025-03-31 00:05:56,622] {taskinstance.py:1240} INFO - 
--------------------------------------------------------------------------------
[2025-03-31 00:05:56,645] {taskinstance.py:1259} INFO - Executing <Task(DataprocCreateClusterOperator): create_dataproc_cluster> on 2025-03-31 00:05:20.585572+00:00
[2025-03-31 00:05:56,661] {standard_task_runner.py:52} INFO - Started process 1675 to run task
[2025-03-31 00:05:56,666] {standard_task_runner.py:76} INFO - Running: ['***', 'tasks', 'run', 'natality_web_data_to_gcs', 'create_dataproc_cluster', 'manual__2025-03-31T00:05:20.585572+00:00', '--job-id', '230', '--raw', '--subdir', 'DAGS_FOLDER/bigquery_to_gcs.py', '--cfg-path', '/tmp/tmp8e2i8u80', '--error-file', '/tmp/tmp36p2op57']
[2025-03-31 00:05:56,673] {standard_task_runner.py:77} INFO - Job 230: Subtask create_dataproc_cluster
[2025-03-31 00:05:56,777] {logging_mixin.py:109} INFO - Running <TaskInstance: natality_web_data_to_gcs.create_dataproc_cluster manual__2025-03-31T00:05:20.585572+00:00 [running]> on host 3341a2d56eeb
[2025-03-31 00:05:56,889] {taskinstance.py:1426} INFO - Exporting the following env vars:
AIRFLOW_CTX_DAG_OWNER=***
AIRFLOW_CTX_DAG_ID=natality_web_data_to_gcs
AIRFLOW_CTX_TASK_ID=create_dataproc_cluster
AIRFLOW_CTX_EXECUTION_DATE=2025-03-31T00:05:20.585572+00:00
AIRFLOW_CTX_DAG_RUN_ID=manual__2025-03-31T00:05:20.585572+00:00
[2025-03-31 00:05:56,890] {dataproc.py:662} INFO - Creating cluster: us-natality-cluster
[2025-03-31 00:05:56,891] {crypto.py:82} WARNING - empty cryptography key - values will not be stored encrypted.
[2025-03-31 00:06:00,349] {taskinstance.py:1700} ERROR - Task failed with exception
Traceback (most recent call last):
  File "/home/airflow/.local/lib/python3.6/site-packages/google/api_core/grpc_helpers.py", line 67, in error_remapped_callable
    return callable_(*args, **kwargs)
  File "/home/airflow/.local/lib/python3.6/site-packages/grpc/_channel.py", line 946, in __call__
    return _end_unary_response_blocking(state, call, False, None)
  File "/home/airflow/.local/lib/python3.6/site-packages/grpc/_channel.py", line 849, in _end_unary_response_blocking
    raise _InactiveRpcError(state)
grpc._channel._InactiveRpcError: <_InactiveRpcError of RPC that terminated with:
	status = StatusCode.INVALID_ARGUMENT
	details = "Multiple validation errors:
 - Creating clusters using the n1-standard-1 machine type is not supported for image version 2.2.51-debian12.
 - Permissions are missing for the default service account '1024460416669-compute@developer.gserviceaccount.com', missing permissions: [storage.buckets.get, storage.objects.create, storage.objects.delete, storage.objects.get, storage.objects.list, storage.objects.update] on the project 'projects/us-natality-455214'. This usually happens when a custom resource (ex: custom staging bucket) or a user-managed VM Service account has been provided and the default/user-managed service account hasn't been granted enough permissions on the resource. See https://cloud.google.com/dataproc/docs/concepts/configuring-clusters/service-accounts#VM_service_account."
	debug_error_string = "{"created":"@1743379560.348024626","description":"Error received from peer ipv4:173.194.195.95:443","file":"src/core/lib/surface/call.cc","file_line":1063,"grpc_message":"Multiple validation errors:\n - Creating clusters using the n1-standard-1 machine type is not supported for image version 2.2.51-debian12.\n - Permissions are missing for the default service account '1024460416669-compute@developer.gserviceaccount.com', missing permissions: [storage.buckets.get, storage.objects.create, storage.objects.delete, storage.objects.get, storage.objects.list, storage.objects.update] on the project 'projects/us-natality-455214'. This usually happens when a custom resource (ex: custom staging bucket) or a user-managed VM Service account has been provided and the default/user-managed service account hasn't been granted enough permissions on the resource. See https://cloud.google.com/dataproc/docs/concepts/configuring-clusters/service-accounts#VM_service_account.","grpc_status":3}"
>

The above exception was the direct cause of the following exception:

Traceback (most recent call last):
  File "/home/airflow/.local/lib/python3.6/site-packages/airflow/models/taskinstance.py", line 1329, in _run_raw_task
    self._execute_task_with_callbacks(context)
  File "/home/airflow/.local/lib/python3.6/site-packages/airflow/models/taskinstance.py", line 1455, in _execute_task_with_callbacks
    result = self._execute_task(context, self.task)
  File "/home/airflow/.local/lib/python3.6/site-packages/airflow/models/taskinstance.py", line 1511, in _execute_task
    result = execute_callable(context=context)
  File "/home/airflow/.local/lib/python3.6/site-packages/airflow/providers/google/cloud/operators/dataproc.py", line 676, in execute
    cluster = self._create_cluster(hook)
  File "/home/airflow/.local/lib/python3.6/site-packages/airflow/providers/google/cloud/operators/dataproc.py", line 603, in _create_cluster
    metadata=self.metadata,
  File "/home/airflow/.local/lib/python3.6/site-packages/airflow/providers/google/common/hooks/base_google.py", line 430, in inner_wrapper
    return func(self, *args, **kwargs)
  File "/home/airflow/.local/lib/python3.6/site-packages/airflow/providers/google/cloud/hooks/dataproc.py", line 365, in create_cluster
    metadata=metadata,
  File "/home/airflow/.local/lib/python3.6/site-packages/google/cloud/dataproc_v1/services/cluster_controller/client.py", line 460, in create_cluster
    response = rpc(request, retry=retry, timeout=timeout, metadata=metadata,)
  File "/home/airflow/.local/lib/python3.6/site-packages/google/api_core/gapic_v1/method.py", line 145, in __call__
    return wrapped_func(*args, **kwargs)
  File "/home/airflow/.local/lib/python3.6/site-packages/google/api_core/timeout.py", line 102, in func_with_timeout
    return func(*args, **kwargs)
  File "/home/airflow/.local/lib/python3.6/site-packages/google/api_core/grpc_helpers.py", line 69, in error_remapped_callable
    six.raise_from(exceptions.from_grpc_error(exc), exc)
  File "<string>", line 3, in raise_from
google.api_core.exceptions.InvalidArgument: 400 Multiple validation errors:
 - Creating clusters using the n1-standard-1 machine type is not supported for image version 2.2.51-debian12.
 - Permissions are missing for the default service account '1024460416669-compute@developer.gserviceaccount.com', missing permissions: [storage.buckets.get, storage.objects.create, storage.objects.delete, storage.objects.get, storage.objects.list, storage.objects.update] on the project 'projects/us-natality-455214'. This usually happens when a custom resource (ex: custom staging bucket) or a user-managed VM Service account has been provided and the default/user-managed service account hasn't been granted enough permissions on the resource. See https://cloud.google.com/dataproc/docs/concepts/configuring-clusters/service-accounts#VM_service_account.
[2025-03-31 00:06:00,374] {taskinstance.py:1277} INFO - Marking task as FAILED. dag_id=natality_web_data_to_gcs, task_id=create_dataproc_cluster, execution_date=20250331T000520, start_date=20250331T000556, end_date=20250331T000600
[2025-03-31 00:06:00,400] {standard_task_runner.py:92} ERROR - Failed to execute job 230 for task create_dataproc_cluster
Traceback (most recent call last):
  File "/home/airflow/.local/lib/python3.6/site-packages/google/api_core/grpc_helpers.py", line 67, in error_remapped_callable
    return callable_(*args, **kwargs)
  File "/home/airflow/.local/lib/python3.6/site-packages/grpc/_channel.py", line 946, in __call__
    return _end_unary_response_blocking(state, call, False, None)
  File "/home/airflow/.local/lib/python3.6/site-packages/grpc/_channel.py", line 849, in _end_unary_response_blocking
    raise _InactiveRpcError(state)
grpc._channel._InactiveRpcError: <_InactiveRpcError of RPC that terminated with:
	status = StatusCode.INVALID_ARGUMENT
	details = "Multiple validation errors:
 - Creating clusters using the n1-standard-1 machine type is not supported for image version 2.2.51-debian12.
 - Permissions are missing for the default service account '1024460416669-compute@developer.gserviceaccount.com', missing permissions: [storage.buckets.get, storage.objects.create, storage.objects.delete, storage.objects.get, storage.objects.list, storage.objects.update] on the project 'projects/us-natality-455214'. This usually happens when a custom resource (ex: custom staging bucket) or a user-managed VM Service account has been provided and the default/user-managed service account hasn't been granted enough permissions on the resource. See https://cloud.google.com/dataproc/docs/concepts/configuring-clusters/service-accounts#VM_service_account."
	debug_error_string = "{"created":"@1743379560.348024626","description":"Error received from peer ipv4:173.194.195.95:443","file":"src/core/lib/surface/call.cc","file_line":1063,"grpc_message":"Multiple validation errors:\n - Creating clusters using the n1-standard-1 machine type is not supported for image version 2.2.51-debian12.\n - Permissions are missing for the default service account '1024460416669-compute@developer.gserviceaccount.com', missing permissions: [storage.buckets.get, storage.objects.create, storage.objects.delete, storage.objects.get, storage.objects.list, storage.objects.update] on the project 'projects/us-natality-455214'. This usually happens when a custom resource (ex: custom staging bucket) or a user-managed VM Service account has been provided and the default/user-managed service account hasn't been granted enough permissions on the resource. See https://cloud.google.com/dataproc/docs/concepts/configuring-clusters/service-accounts#VM_service_account.","grpc_status":3}"
>

The above exception was the direct cause of the following exception:

Traceback (most recent call last):
  File "/home/airflow/.local/lib/python3.6/site-packages/airflow/task/task_runner/standard_task_runner.py", line 85, in _start_by_fork
    args.func(args, dag=self.dag)
  File "/home/airflow/.local/lib/python3.6/site-packages/airflow/cli/cli_parser.py", line 48, in command
    return func(*args, **kwargs)
  File "/home/airflow/.local/lib/python3.6/site-packages/airflow/utils/cli.py", line 92, in wrapper
    return f(*args, **kwargs)
  File "/home/airflow/.local/lib/python3.6/site-packages/airflow/cli/commands/task_command.py", line 298, in task_run
    _run_task_by_selected_method(args, dag, ti)
  File "/home/airflow/.local/lib/python3.6/site-packages/airflow/cli/commands/task_command.py", line 107, in _run_task_by_selected_method
    _run_raw_task(args, ti)
  File "/home/airflow/.local/lib/python3.6/site-packages/airflow/cli/commands/task_command.py", line 184, in _run_raw_task
    error_file=args.error_file,
  File "/home/airflow/.local/lib/python3.6/site-packages/airflow/utils/session.py", line 70, in wrapper
    return func(*args, session=session, **kwargs)
  File "/home/airflow/.local/lib/python3.6/site-packages/airflow/models/taskinstance.py", line 1329, in _run_raw_task
    self._execute_task_with_callbacks(context)
  File "/home/airflow/.local/lib/python3.6/site-packages/airflow/models/taskinstance.py", line 1455, in _execute_task_with_callbacks
    result = self._execute_task(context, self.task)
  File "/home/airflow/.local/lib/python3.6/site-packages/airflow/models/taskinstance.py", line 1511, in _execute_task
    result = execute_callable(context=context)
  File "/home/airflow/.local/lib/python3.6/site-packages/airflow/providers/google/cloud/operators/dataproc.py", line 676, in execute
    cluster = self._create_cluster(hook)
  File "/home/airflow/.local/lib/python3.6/site-packages/airflow/providers/google/cloud/operators/dataproc.py", line 603, in _create_cluster
    metadata=self.metadata,
  File "/home/airflow/.local/lib/python3.6/site-packages/airflow/providers/google/common/hooks/base_google.py", line 430, in inner_wrapper
    return func(self, *args, **kwargs)
  File "/home/airflow/.local/lib/python3.6/site-packages/airflow/providers/google/cloud/hooks/dataproc.py", line 365, in create_cluster
    metadata=metadata,
  File "/home/airflow/.local/lib/python3.6/site-packages/google/cloud/dataproc_v1/services/cluster_controller/client.py", line 460, in create_cluster
    response = rpc(request, retry=retry, timeout=timeout, metadata=metadata,)
  File "/home/airflow/.local/lib/python3.6/site-packages/google/api_core/gapic_v1/method.py", line 145, in __call__
    return wrapped_func(*args, **kwargs)
  File "/home/airflow/.local/lib/python3.6/site-packages/google/api_core/timeout.py", line 102, in func_with_timeout
    return func(*args, **kwargs)
  File "/home/airflow/.local/lib/python3.6/site-packages/google/api_core/grpc_helpers.py", line 69, in error_remapped_callable
    six.raise_from(exceptions.from_grpc_error(exc), exc)
  File "<string>", line 3, in raise_from
google.api_core.exceptions.InvalidArgument: 400 Multiple validation errors:
 - Creating clusters using the n1-standard-1 machine type is not supported for image version 2.2.51-debian12.
 - Permissions are missing for the default service account '1024460416669-compute@developer.gserviceaccount.com', missing permissions: [storage.buckets.get, storage.objects.create, storage.objects.delete, storage.objects.get, storage.objects.list, storage.objects.update] on the project 'projects/us-natality-455214'. This usually happens when a custom resource (ex: custom staging bucket) or a user-managed VM Service account has been provided and the default/user-managed service account hasn't been granted enough permissions on the resource. See https://cloud.google.com/dataproc/docs/concepts/configuring-clusters/service-accounts#VM_service_account.
[2025-03-31 00:06:00,440] {local_task_job.py:154} INFO - Task exited with return code 1
[2025-03-31 00:06:00,492] {local_task_job.py:264} INFO - 0 downstream tasks scheduled from follow-on schedule check
