[2025-03-30 23:59:12,782] {taskinstance.py:1032} INFO - Dependencies all met for <TaskInstance: natality_web_data_to_gcs.create_dataproc_cluster manual__2025-03-30T23:58:36.673425+00:00 [queued]>
[2025-03-30 23:59:12,796] {taskinstance.py:1032} INFO - Dependencies all met for <TaskInstance: natality_web_data_to_gcs.create_dataproc_cluster manual__2025-03-30T23:58:36.673425+00:00 [queued]>
[2025-03-30 23:59:12,796] {taskinstance.py:1238} INFO - 
--------------------------------------------------------------------------------
[2025-03-30 23:59:12,796] {taskinstance.py:1239} INFO - Starting attempt 1 of 1
[2025-03-30 23:59:12,796] {taskinstance.py:1240} INFO - 
--------------------------------------------------------------------------------
[2025-03-30 23:59:12,812] {taskinstance.py:1259} INFO - Executing <Task(DataprocCreateClusterOperator): create_dataproc_cluster> on 2025-03-30 23:58:36.673425+00:00
[2025-03-30 23:59:12,828] {standard_task_runner.py:52} INFO - Started process 1181 to run task
[2025-03-30 23:59:12,833] {standard_task_runner.py:76} INFO - Running: ['***', 'tasks', 'run', 'natality_web_data_to_gcs', 'create_dataproc_cluster', 'manual__2025-03-30T23:58:36.673425+00:00', '--job-id', '208', '--raw', '--subdir', 'DAGS_FOLDER/bigquery_to_gcs.py', '--cfg-path', '/tmp/tmpfww9j1uy', '--error-file', '/tmp/tmpienat60z']
[2025-03-30 23:59:12,839] {standard_task_runner.py:77} INFO - Job 208: Subtask create_dataproc_cluster
[2025-03-30 23:59:12,938] {logging_mixin.py:109} INFO - Running <TaskInstance: natality_web_data_to_gcs.create_dataproc_cluster manual__2025-03-30T23:58:36.673425+00:00 [running]> on host 3341a2d56eeb
[2025-03-30 23:59:13,037] {taskinstance.py:1426} INFO - Exporting the following env vars:
AIRFLOW_CTX_DAG_OWNER=***
AIRFLOW_CTX_DAG_ID=natality_web_data_to_gcs
AIRFLOW_CTX_TASK_ID=create_dataproc_cluster
AIRFLOW_CTX_EXECUTION_DATE=2025-03-30T23:58:36.673425+00:00
AIRFLOW_CTX_DAG_RUN_ID=manual__2025-03-30T23:58:36.673425+00:00
[2025-03-30 23:59:13,040] {dataproc.py:662} INFO - Creating cluster: us-natality-cluster
[2025-03-30 23:59:13,042] {crypto.py:82} WARNING - empty cryptography key - values will not be stored encrypted.
[2025-03-30 23:59:13,099] {taskinstance.py:1700} ERROR - Task failed with exception
Traceback (most recent call last):
  File "/home/airflow/.local/lib/python3.6/site-packages/airflow/models/taskinstance.py", line 1329, in _run_raw_task
    self._execute_task_with_callbacks(context)
  File "/home/airflow/.local/lib/python3.6/site-packages/airflow/models/taskinstance.py", line 1455, in _execute_task_with_callbacks
    result = self._execute_task(context, self.task)
  File "/home/airflow/.local/lib/python3.6/site-packages/airflow/models/taskinstance.py", line 1511, in _execute_task
    result = execute_callable(context=context)
  File "/home/airflow/.local/lib/python3.6/site-packages/airflow/providers/google/cloud/operators/dataproc.py", line 676, in execute
    cluster = self._create_cluster(hook)
  File "/home/airflow/.local/lib/python3.6/site-packages/airflow/providers/google/cloud/operators/dataproc.py", line 603, in _create_cluster
    metadata=self.metadata,
  File "/home/airflow/.local/lib/python3.6/site-packages/airflow/providers/google/common/hooks/base_google.py", line 430, in inner_wrapper
    return func(self, *args, **kwargs)
  File "/home/airflow/.local/lib/python3.6/site-packages/airflow/providers/google/cloud/hooks/dataproc.py", line 365, in create_cluster
    metadata=metadata,
  File "/home/airflow/.local/lib/python3.6/site-packages/google/cloud/dataproc_v1/services/cluster_controller/client.py", line 445, in create_cluster
    request = clusters.CreateClusterRequest(request)
  File "/home/airflow/.local/lib/python3.6/site-packages/proto/message.py", line 516, in __init__
    pb_value = marshal.to_proto(pb_type, value)
  File "/home/airflow/.local/lib/python3.6/site-packages/proto/marshal/marshal.py", line 211, in to_proto
    pb_value = rule.to_proto(value)
  File "/home/airflow/.local/lib/python3.6/site-packages/proto/marshal/rules/message.py", line 36, in to_proto
    return self._descriptor(**value)
ValueError: Protocol message ClusterConfig has no "config" field.
[2025-03-30 23:59:13,124] {taskinstance.py:1277} INFO - Marking task as FAILED. dag_id=natality_web_data_to_gcs, task_id=create_dataproc_cluster, execution_date=20250330T235836, start_date=20250330T235912, end_date=20250330T235913
[2025-03-30 23:59:13,282] {standard_task_runner.py:92} ERROR - Failed to execute job 208 for task create_dataproc_cluster
Traceback (most recent call last):
  File "/home/airflow/.local/lib/python3.6/site-packages/airflow/task/task_runner/standard_task_runner.py", line 85, in _start_by_fork
    args.func(args, dag=self.dag)
  File "/home/airflow/.local/lib/python3.6/site-packages/airflow/cli/cli_parser.py", line 48, in command
    return func(*args, **kwargs)
  File "/home/airflow/.local/lib/python3.6/site-packages/airflow/utils/cli.py", line 92, in wrapper
    return f(*args, **kwargs)
  File "/home/airflow/.local/lib/python3.6/site-packages/airflow/cli/commands/task_command.py", line 298, in task_run
    _run_task_by_selected_method(args, dag, ti)
  File "/home/airflow/.local/lib/python3.6/site-packages/airflow/cli/commands/task_command.py", line 107, in _run_task_by_selected_method
    _run_raw_task(args, ti)
  File "/home/airflow/.local/lib/python3.6/site-packages/airflow/cli/commands/task_command.py", line 184, in _run_raw_task
    error_file=args.error_file,
  File "/home/airflow/.local/lib/python3.6/site-packages/airflow/utils/session.py", line 70, in wrapper
    return func(*args, session=session, **kwargs)
  File "/home/airflow/.local/lib/python3.6/site-packages/airflow/models/taskinstance.py", line 1329, in _run_raw_task
    self._execute_task_with_callbacks(context)
  File "/home/airflow/.local/lib/python3.6/site-packages/airflow/models/taskinstance.py", line 1455, in _execute_task_with_callbacks
    result = self._execute_task(context, self.task)
  File "/home/airflow/.local/lib/python3.6/site-packages/airflow/models/taskinstance.py", line 1511, in _execute_task
    result = execute_callable(context=context)
  File "/home/airflow/.local/lib/python3.6/site-packages/airflow/providers/google/cloud/operators/dataproc.py", line 676, in execute
    cluster = self._create_cluster(hook)
  File "/home/airflow/.local/lib/python3.6/site-packages/airflow/providers/google/cloud/operators/dataproc.py", line 603, in _create_cluster
    metadata=self.metadata,
  File "/home/airflow/.local/lib/python3.6/site-packages/airflow/providers/google/common/hooks/base_google.py", line 430, in inner_wrapper
    return func(self, *args, **kwargs)
  File "/home/airflow/.local/lib/python3.6/site-packages/airflow/providers/google/cloud/hooks/dataproc.py", line 365, in create_cluster
    metadata=metadata,
  File "/home/airflow/.local/lib/python3.6/site-packages/google/cloud/dataproc_v1/services/cluster_controller/client.py", line 445, in create_cluster
    request = clusters.CreateClusterRequest(request)
  File "/home/airflow/.local/lib/python3.6/site-packages/proto/message.py", line 516, in __init__
    pb_value = marshal.to_proto(pb_type, value)
  File "/home/airflow/.local/lib/python3.6/site-packages/proto/marshal/marshal.py", line 211, in to_proto
    pb_value = rule.to_proto(value)
  File "/home/airflow/.local/lib/python3.6/site-packages/proto/marshal/rules/message.py", line 36, in to_proto
    return self._descriptor(**value)
ValueError: Protocol message ClusterConfig has no "config" field.
[2025-03-30 23:59:13,376] {local_task_job.py:154} INFO - Task exited with return code 1
[2025-03-30 23:59:13,447] {local_task_job.py:264} INFO - 0 downstream tasks scheduled from follow-on schedule check
